  File "/home/runner/workspace/.pythonlibs/lib/python3.11/site-packages/sqlalchemy/sql/elements.py", line 523, in _execute_on_connection
    return connection._execute_clauseelement(
           ^^^^^^^^^^^^^^^^^^^^^^^^^^^^^^^^^^
  File "/home/runner/workspace/.pythonlibs/lib/python3.11/site-packages/sqlalchemy/engine/base.py", line 1637, in _execute_clauseelement
    ret = self._execute_context(
          ^^^^^^^^^^^^^^^^^^^^^^
  File "/home/runner/workspace/.pythonlibs/lib/python3.11/site-packages/sqlalchemy/engine/base.py", line 1842, in _execute_context
    return self._exec_single_context(
           ^^^^^^^^^^^^^^^^^^^^^^^^^^
  File "/home/runner/workspace/.pythonlibs/lib/python3.11/site-packages/sqlalchemy/engine/base.py", line 1982, in _exec_single_context
    self._handle_dbapi_exception(
  File "/home/runner/workspace/.pythonlibs/lib/python3.11/site-packages/sqlalchemy/engine/base.py", line 2351, in _handle_dbapi_exception
    raise sqlalchemy_exception.with_traceback(exc_info[2]) from e
  File "/home/runner/workspace/.pythonlibs/lib/python3.11/site-packages/sqlalchemy/engine/base.py", line 1963, in _exec_single_context
    self.dialect.do_execute(
  File "/home/runner/workspace/.pythonlibs/lib/python3.11/site-packages/sqlalchemy/engine/default.py", line 943, in do_execute
    cursor.execute(statement, parameters)
sqlalchemy.exc.ProgrammingError: (psycopg2.errors.UndefinedColumn) column "invite_token" of relation "trips" does not exist
LINE 1: ...destination, start_date, end_date, budget, state, invite_tok...
                                                             ^

[SQL: INSERT INTO trips (trip_id, title, destination, start_date, end_date, budget, state, invite_token, created_at, updated_at) VALUES (%(trip_id)s, %(title)s, %(destination)s, %(start_date)s, %(end_date)s, %(budget)s, %(state)s, %(invite_token)s, %(created_at)s, %(updated_at)s) RETURNING trips.id]
[parameters: {'trip_id': 'POR-2025-731', 'title': 'Porto Weekend', 'destination': 'Porto', 'start_date': None, 'end_date': None, 'budget': None, 'state': 'COLLECTING_DATES', 'invite_token': 'NOBJw0pq509XILrYDtgNTPvVi9WSehs35QRgChHiXQw', 'created_at': datetime.datetime(2025, 7, 7, 1, 34, 51, 714193), 'updated_at': datetime.datetime(2025, 7, 7, 1, 34, 51, 714197)}]
(Background on this error at: https://sqlalche.me/e/20/f405)